<?xml version='1.0' encoding='utf-8'?>
<robot name="j2s6s300">
  
  
  <mujoco><compiler meshdir="../meshes/" balanceinertia="true" discardvisual="false" /></mujoco>

<link name="base_link" />
  
  <gazebo>
    <plugin filename="libgazebo_ros_control.so" name="gazebo_ros_control">
      <robotNamespace>j2s6s300</robotNamespace>
      <robotSimType>gazebo_ros_control/DefaultRobotHWSim</robotSimType>
      <legacyModeNS>true</legacyModeNS>
    </plugin>
  </gazebo>
  <link name="j2s6s300_link_base">
    <visual>
      <geometry>
        <mesh filename="package://kinova_description/meshes/base.STL" />
      </geometry>
      <material name="carbon_fiber">
        <color rgba="0.792156862745098 0.819607843137255 0.933333333333333 1" />
      </material>
    </visual>
    <collision>
      <geometry>
        <mesh filename="package://kinova_description/meshes/base.STL" />
      </geometry>
    </collision>
    <inertial>
      <mass value="0.46784" />
      <origin rpy="0 0 0" xyz="0 0 0.1255" />
      <inertia ixx="0.000951270861568" ixy="0" ixz="0" iyy="0.000951270861568" iyz="0" izz="0.00037427200000000004" />
    </inertial>
  </link>
  <joint name="j2s6s300_joint_base" type="fixed">
    <parent link="base_link" />
    <child link="j2s6s300_link_base" />
    <axis xyz="0 0 0" />
    <origin rpy="0 0 0" xyz="0 0 0" />
    <dynamics damping="0.0" friction="0.0" />
  </joint>
  <link name="j2s6s300_link_1">
    <visual>
      <geometry>
        <mesh filename="package://kinova_description/meshes/shoulder.STL" />
      </geometry>
      <material name="carbon_fiber">
        <color rgba="0.792156862745098 0.819607843137255 0.933333333333333 1" />
      </material>
    </visual>
    <visual>
      <geometry>
        <mesh filename="package://kinova_description/meshes/ring_big.STL" />
      </geometry>
    </visual>
    <collision>
      <geometry>
        <mesh filename="package://kinova_description/meshes/shoulder.STL" />
      </geometry>
    </collision>
    <inertial>
      <mass value="0.7477" />
      <origin xyz="0 -0.002 -0.0605" />
      <inertia ixx="0.0015203172520400004" ixy="0" ixz="0" iyy="0.0015203172520400004" iyz="0" izz="0.00059816" />
    </inertial>
  </link>
  <joint name="j2s6s300_joint_1" type="continuous">
    <parent link="j2s6s300_link_base" />
    <child link="j2s6s300_link_1" />
    <axis xyz="0 0 1" />
    <limit effort="40" velocity="0.6283185307179586" />
    <origin rpy="0 3.141592653589793 0" xyz="0 0 0.15675" />
    <dynamics damping="0.0" friction="0.0" />
  </joint>
  <transmission name="j2s6s300_joint_1_trans">
    <type>transmission_interface/SimpleTransmission</type>
    <joint name="j2s6s300_joint_1">
      <hardwareInterface>hardware_interface/EffortJointInterface</hardwareInterface>
    </joint>
    <actuator name="j2s6s300_joint_1_actuator">
      <hardwareInterface>hardware_interface/EffortJointInterface</hardwareInterface>
      <mechanicalReduction>160</mechanicalReduction>
    </actuator>
  </transmission>
  
  <gazebo reference="j2s6s300_joint_1">
    <provideFeedback>true</provideFeedback>
  </gazebo>
  <gazebo>
    <plugin filename="libgazebo_ros_ft_sensor.so" name="ft_sensor">
      <updateRate>30.0</updateRate>
      <topicName>j2s6s300_joint_1_ft_sensor_topic</topicName>
      <jointName>j2s6s300_joint_1</jointName>
    </plugin>
  </gazebo>
  <link name="j2s6s300_link_2">
    <visual>
      <geometry>
        <mesh filename="package://kinova_description/meshes/arm.STL" />
      </geometry>
      <material name="carbon_fiber">
        <color rgba="0.792156862745098 0.819607843137255 0.933333333333333 1" />
      </material>
    </visual>
    <visual>
      <geometry>
        <mesh filename="package://kinova_description/meshes/ring_big.STL" />
      </geometry>
    </visual>
    <collision>
      <geometry>
        <mesh filename="package://kinova_description/meshes/arm.STL" />
      </geometry>
    </collision>
    <inertial>
      <mass value="0.99" />
      <origin xyz="0 -0.2065 -0.01" />
      <inertia ixx="0.010502207990999999" ixy="0" ixz="0" iyy="0.0007920000000000001" iyz="0" izz="0.010502207990999999" />
    </inertial>
  </link>
  <joint name="j2s6s300_joint_2" type="revolute">
    <parent link="j2s6s300_link_1" />
    <child link="j2s6s300_link_2" />
    <axis xyz="0 0 1" />
    <limit effort="80" lower="0.8203047484373349" upper="5.462880558742252" velocity="0.6283185307179586" />
    <origin rpy="-1.5707963267948966 0 3.141592653589793" xyz="0 0.0016 -0.11875" />
    <dynamics damping="0.0" friction="0.0" />
  </joint>
  <transmission name="j2s6s300_joint_2_trans">
    <type>transmission_interface/SimpleTransmission</type>
    <joint name="j2s6s300_joint_2">
      <hardwareInterface>hardware_interface/EffortJointInterface</hardwareInterface>
    </joint>
    <actuator name="j2s6s300_joint_2_actuator">
      <hardwareInterface>hardware_interface/EffortJointInterface</hardwareInterface>
      <mechanicalReduction>160</mechanicalReduction>
    </actuator>
  </transmission>
  
  <gazebo reference="j2s6s300_joint_2">
    <provideFeedback>true</provideFeedback>
  </gazebo>
  <gazebo>
    <plugin filename="libgazebo_ros_ft_sensor.so" name="ft_sensor">
      <updateRate>30.0</updateRate>
      <topicName>j2s6s300_joint_2_ft_sensor_topic</topicName>
      <jointName>j2s6s300_joint_2</jointName>
    </plugin>
  </gazebo>
  <link name="j2s6s300_link_3">
    <visual>
      <geometry>
        <mesh filename="package://kinova_description/meshes/forearm.STL" />
      </geometry>
      <material name="carbon_fiber">
        <color rgba="0.792156862745098 0.819607843137255 0.933333333333333 1" />
      </material>
    </visual>
    <visual>
      <geometry>
        <mesh filename="package://kinova_description/meshes/ring_big.STL" />
      </geometry>
    </visual>
    <collision>
      <geometry>
        <mesh filename="package://kinova_description/meshes/forearm.STL" />
      </geometry>
    </collision>
    <inertial>
      <mass value="0.6763" />
      <origin xyz="0 0.081 -0.0086" />
      <inertia ixx="0.0014202243190800001" ixy="0" ixz="0" iyy="0.000304335" iyz="0" izz="0.0014202243190800001" />
    </inertial>
  </link>
  <joint name="j2s6s300_joint_3" type="revolute">
    <parent link="j2s6s300_link_2" />
    <child link="j2s6s300_link_3" />
    <axis xyz="0 0 1" />
    <limit effort="40" lower="0.33161255787892263" upper="5.951572749300664" velocity="0.6283185307179586" />
    <origin rpy="0 3.141592653589793 0" xyz="0 -0.410 0" />
    <dynamics damping="0.0" friction="0.0" />
  </joint>
  <transmission name="j2s6s300_joint_3_trans">
    <type>transmission_interface/SimpleTransmission</type>
    <joint name="j2s6s300_joint_3">
      <hardwareInterface>hardware_interface/EffortJointInterface</hardwareInterface>
    </joint>
    <actuator name="j2s6s300_joint_3_actuator">
      <hardwareInterface>hardware_interface/EffortJointInterface</hardwareInterface>
      <mechanicalReduction>160</mechanicalReduction>
    </actuator>
  </transmission>
  
  <gazebo reference="j2s6s300_joint_3">
    <provideFeedback>true</provideFeedback>
  </gazebo>
  <gazebo>
    <plugin filename="libgazebo_ros_ft_sensor.so" name="ft_sensor">
      <updateRate>30.0</updateRate>
      <topicName>j2s6s300_joint_3_ft_sensor_topic</topicName>
      <jointName>j2s6s300_joint_3</jointName>
    </plugin>
  </gazebo>
  <link name="j2s6s300_link_4">
    <visual>
      <geometry>
        <mesh filename="package://kinova_description/meshes/wrist_spherical_1.STL" />
      </geometry>
      <material name="carbon_fiber">
        <color rgba="0.792156862745098 0.819607843137255 0.933333333333333 1" />
      </material>
    </visual>
    <visual>
      <geometry>
        <mesh filename="package://kinova_description/meshes/ring_small.STL" />
      </geometry>
    </visual>
    <collision>
      <geometry>
        <mesh filename="package://kinova_description/meshes/wrist_spherical_1.STL" />
      </geometry>
    </collision>
    <inertial>
      <mass value="0.463" />
      <origin xyz="0 0.0028848942 -0.0541932613" />
      <inertia ixx="0.0004321316048000001" ixy="0" ixz="0" iyy="0.0004321316048000001" iyz="0" izz="9.260000000000001e-05" />
    </inertial>
  </link>
  <joint name="j2s6s300_joint_4" type="continuous">
    <parent link="j2s6s300_link_3" />
    <child link="j2s6s300_link_4" />
    <axis xyz="0 0 1" />
    <limit effort="20" velocity="0.8377580409572781" />
    <origin rpy="-1.5707963267948966 0 3.141592653589793" xyz="0 0.2073 -0.0114" />
    <dynamics damping="0.0" friction="0.0" />
  </joint>
  <transmission name="j2s6s300_joint_4_trans">
    <type>transmission_interface/SimpleTransmission</type>
    <joint name="j2s6s300_joint_4">
      <hardwareInterface>hardware_interface/EffortJointInterface</hardwareInterface>
    </joint>
    <actuator name="j2s6s300_joint_4_actuator">
      <hardwareInterface>hardware_interface/EffortJointInterface</hardwareInterface>
      <mechanicalReduction>160</mechanicalReduction>
    </actuator>
  </transmission>
  
  <gazebo reference="j2s6s300_joint_4">
    <provideFeedback>true</provideFeedback>
  </gazebo>
  <gazebo>
    <plugin filename="libgazebo_ros_ft_sensor.so" name="ft_sensor">
      <updateRate>30.0</updateRate>
      <topicName>j2s6s300_joint_4_ft_sensor_topic</topicName>
      <jointName>j2s6s300_joint_4</jointName>
    </plugin>
  </gazebo>
  <link name="j2s6s300_link_5">
    <visual>
      <geometry>
        <mesh filename="package://kinova_description/meshes/wrist_spherical_2.STL" />
      </geometry>
      <material name="carbon_fiber">
        <color rgba="0.792156862745098 0.819607843137255 0.933333333333333 1" />
      </material>
    </visual>
    <visual>
      <geometry>
        <mesh filename="package://kinova_description/meshes/ring_small.STL" />
      </geometry>
    </visual>
    <collision>
      <geometry>
        <mesh filename="package://kinova_description/meshes/wrist_spherical_2.STL" />
      </geometry>
    </collision>
    <inertial>
      <mass value="0.463" />
      <origin xyz="0 0.0497208855 -0.0028562765" />
      <inertia ixx="0.0004321316048000001" ixy="0" ixz="0" iyy="9.260000000000001e-05" iyz="0" izz="0.0004321316048000001" />
    </inertial>
  </link>
  <joint name="j2s6s300_joint_5" type="revolute">
    <parent link="j2s6s300_link_4" />
    <child link="j2s6s300_link_5" />
    <axis xyz="0 0 1" />
    <limit effort="20" lower="0.5235987755982988" upper="5.759586531581287" velocity="0.8377580409572781" />
    <origin rpy="1.5707963267948966 0 3.141592653589793" xyz="0 0 -0.10375" />
    <dynamics damping="0.0" friction="0.0" />
  </joint>
  <transmission name="j2s6s300_joint_5_trans">
    <type>transmission_interface/SimpleTransmission</type>
    <joint name="j2s6s300_joint_5">
      <hardwareInterface>hardware_interface/EffortJointInterface</hardwareInterface>
    </joint>
    <actuator name="j2s6s300_joint_5_actuator">
      <hardwareInterface>hardware_interface/EffortJointInterface</hardwareInterface>
      <mechanicalReduction>160</mechanicalReduction>
    </actuator>
  </transmission>
  
  <gazebo reference="j2s6s300_joint_5">
    <provideFeedback>true</provideFeedback>
  </gazebo>
  <gazebo>
    <plugin filename="libgazebo_ros_ft_sensor.so" name="ft_sensor">
      <updateRate>30.0</updateRate>
      <topicName>j2s6s300_joint_5_ft_sensor_topic</topicName>
      <jointName>j2s6s300_joint_5</jointName>
    </plugin>
  </gazebo>
  <link name="j2s6s300_link_6">
    <visual>
      <geometry>
        <mesh filename="package://kinova_description/meshes/hand_3finger.STL" />
      </geometry>
      <material name="carbon_fiber">
        <color rgba="0.792156862745098 0.819607843137255 0.933333333333333 1" />
      </material>
    </visual>
    <visual>
      <geometry>
        <mesh filename="package://kinova_description/meshes/ring_small.STL" />
      </geometry>
    </visual>
    <collision>
      <geometry>
        <mesh filename="package://kinova_description/meshes/hand_3finger.STL" />
      </geometry>
    </collision>
    <inertial>
      <mass value="0.99" />
      <origin xyz="0 0 -0.06" />
      <inertia ixx="0.00034532361869999995" ixy="0" ixz="0" iyy="0.00034532361869999995" iyz="0" izz="0.0005815999999999999" />
    </inertial>
  </link>
  <joint name="j2s6s300_joint_6" type="continuous">
    <parent link="j2s6s300_link_5" />
    <child link="j2s6s300_link_6" />
    <axis xyz="0 0 1" />
    <limit effort="20" velocity="0.8377580409572781" />
    <origin rpy="-1.5707963267948966 0 3.141592653589793" xyz="0 0.10375 0" />
    <dynamics damping="0.0" friction="0.0" />
  </joint>
  <transmission name="j2s6s300_joint_6_trans">
    <type>transmission_interface/SimpleTransmission</type>
    <joint name="j2s6s300_joint_6">
      <hardwareInterface>hardware_interface/EffortJointInterface</hardwareInterface>
    </joint>
    <actuator name="j2s6s300_joint_6_actuator">
      <hardwareInterface>hardware_interface/EffortJointInterface</hardwareInterface>
      <mechanicalReduction>160</mechanicalReduction>
    </actuator>
  </transmission>
  
  <gazebo reference="j2s6s300_joint_6">
    <provideFeedback>true</provideFeedback>
  </gazebo>
  <gazebo>
    <plugin filename="libgazebo_ros_ft_sensor.so" name="ft_sensor">
      <updateRate>30.0</updateRate>
      <topicName>j2s6s300_joint_6_ft_sensor_topic</topicName>
      <jointName>j2s6s300_joint_6</jointName>
    </plugin>
  </gazebo>
  <link name="j2s6s300_end_effector" />
  <joint name="j2s6s300_joint_end_effector" type="fixed">
    <parent link="j2s6s300_link_6" />
    <child link="j2s6s300_end_effector" />
    <axis xyz="0 0 0" />
    <origin rpy="3.141592653589793 0 1.5707963267948966" xyz="0 0 -0.1600" />
  </joint>
  <link name="j2s6s300_link_finger_1">
    <visual>
      <geometry>
        <mesh filename="package://kinova_description/meshes/finger_proximal.STL" />
      </geometry>
      <material name="carbon_fiber">
        <color rgba="0.792156862745098 0.819607843137255 0.933333333333333 1" />
      </material>
    </visual>
    <collision>
      <geometry>
        <mesh filename="package://kinova_description/meshes/finger_proximal.STL" />
      </geometry>
    </collision>
    <inertial>
      <mass value="0.01" />
      <origin xyz="0.022 0 0" />
      <inertia ixx="7.8999684e-07" ixy="0" ixz="0" iyy="7.8999684e-07" iyz="0" izz="8e-08" />
    </inertial>
  </link>
  <joint name="j2s6s300_joint_finger_1" type="revolute">
    <parent link="j2s6s300_link_6" />
    <child link="j2s6s300_link_finger_1" />
    <axis xyz="0 0 1" />
    <origin rpy="-1.7047873384941834 0.6476144647144773 1.67317415161155" xyz="0.00279 0.03126 -0.11467" />
    <limit effort="2" lower="0" upper="1.51" velocity="1" />
  </joint>
  <transmission name="j2s6s300_joint_finger_1_trans">
    <type>transmission_interface/SimpleTransmission</type>
    <joint name="j2s6s300_joint_finger_1">
      <hardwareInterface>hardware_interface/EffortJointInterface</hardwareInterface>
    </joint>
    <actuator name="j2s6s300_joint_finger_1_actuator">
      <hardwareInterface>hardware_interface/EffortJointInterface</hardwareInterface>
      <mechanicalReduction>1</mechanicalReduction>
    </actuator>
  </transmission>
  <link name="j2s6s300_link_finger_tip_1">
    <visual>
      <geometry>
        <mesh filename="package://kinova_description/meshes/finger_distal.STL" />
      </geometry>
      <material name="carbon_fiber">
        <color rgba="0.792156862745098 0.819607843137255 0.933333333333333 1" />
      </material>
    </visual>
    <collision>
      <geometry>
        <mesh filename="package://kinova_description/meshes/finger_distal.STL" />
      </geometry>
    </collision>
    <inertial>
      <mass value="0.01" />
      <origin xyz="0.022 0 0" />
      <inertia ixx="7.8999684e-07" ixy="0" ixz="0" iyy="7.8999684e-07" iyz="0" izz="8e-08" />
    </inertial>
  </link>
  <joint name="j2s6s300_joint_finger_tip_1" type="revolute">
    <parent link="j2s6s300_link_finger_1" />
    <child link="j2s6s300_link_finger_tip_1" />
    <axis xyz="0 0 1" />
    <origin rpy="0 0 0" xyz="0.044 -0.003 0" />
    <limit effort="2" lower="0" upper="2" velocity="1" />
  </joint>
  <transmission name="j2s6s300_joint_finger_tip_1_trans">
    <type>transmission_interface/SimpleTransmission</type>
    <joint name="j2s6s300_joint_finger_tip_1">
      <hardwareInterface>hardware_interface/EffortJointInterface</hardwareInterface>
    </joint>
    <actuator name="j2s6s300_joint_finger_tip_1_actuator">
      <hardwareInterface>hardware_interface/EffortJointInterface</hardwareInterface>
      <mechanicalReduction>1</mechanicalReduction>
    </actuator>
  </transmission>
  <link name="j2s6s300_link_finger_2">
    <visual>
      <geometry>
        <mesh filename="package://kinova_description/meshes/finger_proximal.STL" />
      </geometry>
      <material name="carbon_fiber">
        <color rgba="0.792156862745098 0.819607843137255 0.933333333333333 1" />
      </material>
    </visual>
    <collision>
      <geometry>
        <mesh filename="package://kinova_description/meshes/finger_proximal.STL" />
      </geometry>
    </collision>
    <inertial>
      <mass value="0.01" />
      <origin xyz="0.022 0 0" />
      <inertia ixx="7.8999684e-07" ixy="0" ixz="0" iyy="7.8999684e-07" iyz="0" izz="8e-08" />
    </inertial>
  </link>
  <joint name="j2s6s300_joint_finger_2" type="revolute">
    <parent link="j2s6s300_link_6" />
    <child link="j2s6s300_link_finger_2" />
    <axis xyz="0 0 1" />
    <origin rpy="-1.570796327 .649262481663582 -1.38614049188413" xyz="0.02226 -0.02707 -0.11482" />
    <limit effort="2" lower="0" upper="1.51" velocity="1" />
  </joint>
  <transmission name="j2s6s300_joint_finger_2_trans">
    <type>transmission_interface/SimpleTransmission</type>
    <joint name="j2s6s300_joint_finger_2">
      <hardwareInterface>hardware_interface/EffortJointInterface</hardwareInterface>
    </joint>
    <actuator name="j2s6s300_joint_finger_2_actuator">
      <hardwareInterface>hardware_interface/EffortJointInterface</hardwareInterface>
      <mechanicalReduction>1</mechanicalReduction>
    </actuator>
  </transmission>
  <link name="j2s6s300_link_finger_tip_2">
    <visual>
      <geometry>
        <mesh filename="package://kinova_description/meshes/finger_distal.STL" />
      </geometry>
      <material name="carbon_fiber">
        <color rgba="0.792156862745098 0.819607843137255 0.933333333333333 1" />
      </material>
    </visual>
    <collision>
      <geometry>
        <mesh filename="package://kinova_description/meshes/finger_distal.STL" />
      </geometry>
    </collision>
    <inertial>
      <mass value="0.01" />
      <origin xyz="0.022 0 0" />
      <inertia ixx="7.8999684e-07" ixy="0" ixz="0" iyy="7.8999684e-07" iyz="0" izz="8e-08" />
    </inertial>
  </link>
  <joint name="j2s6s300_joint_finger_tip_2" type="revolute">
    <parent link="j2s6s300_link_finger_2" />
    <child link="j2s6s300_link_finger_tip_2" />
    <axis xyz="0 0 1" />
    <origin rpy="0 0 0" xyz="0.044 -0.003 0" />
    <limit effort="2" lower="0" upper="2" velocity="1" />
  </joint>
  <transmission name="j2s6s300_joint_finger_tip_2_trans">
    <type>transmission_interface/SimpleTransmission</type>
    <joint name="j2s6s300_joint_finger_tip_2">
      <hardwareInterface>hardware_interface/EffortJointInterface</hardwareInterface>
    </joint>
    <actuator name="j2s6s300_joint_finger_tip_2_actuator">
      <hardwareInterface>hardware_interface/EffortJointInterface</hardwareInterface>
      <mechanicalReduction>1</mechanicalReduction>
    </actuator>
  </transmission>
  <link name="j2s6s300_link_finger_3">
    <visual>
      <geometry>
        <mesh filename="package://kinova_description/meshes/finger_proximal.STL" />
      </geometry>
      <material name="carbon_fiber">
        <color rgba="0.792156862745098 0.819607843137255 0.933333333333333 1" />
      </material>
    </visual>
    <collision>
      <geometry>
        <mesh filename="package://kinova_description/meshes/finger_proximal.STL" />
      </geometry>
    </collision>
    <inertial>
      <mass value="0.01" />
      <origin xyz="0.022 0 0" />
      <inertia ixx="7.8999684e-07" ixy="0" ixz="0" iyy="7.8999684e-07" iyz="0" izz="8e-08" />
    </inertial>
  </link>
  <joint name="j2s6s300_joint_finger_3" type="revolute">
    <parent link="j2s6s300_link_6" />
    <child link="j2s6s300_link_finger_3" />
    <axis xyz="0 0 1" />
    <origin rpy="-1.570796327 .649262481663582 -1.75545216211587" xyz="-0.02226 -0.02707 -0.11482" />
    <limit effort="2" lower="0" upper="1.51" velocity="1" />
  </joint>
  <transmission name="j2s6s300_joint_finger_3_trans">
    <type>transmission_interface/SimpleTransmission</type>
    <joint name="j2s6s300_joint_finger_3">
      <hardwareInterface>hardware_interface/EffortJointInterface</hardwareInterface>
    </joint>
    <actuator name="j2s6s300_joint_finger_3_actuator">
      <hardwareInterface>hardware_interface/EffortJointInterface</hardwareInterface>
      <mechanicalReduction>1</mechanicalReduction>
    </actuator>
  </transmission>
  <link name="j2s6s300_link_finger_tip_3">
    <visual>
      <geometry>
        <mesh filename="package://kinova_description/meshes/finger_distal.STL" />
      </geometry>
      <material name="carbon_fiber">
        <color rgba="0.792156862745098 0.819607843137255 0.933333333333333 1" />
      </material>
    </visual>
    <collision>
      <geometry>
        <mesh filename="package://kinova_description/meshes/finger_distal.STL" />
      </geometry>
    </collision>
    <inertial>
      <mass value="0.01" />
      <origin xyz="0.022 0 0" />
      <inertia ixx="7.8999684e-07" ixy="0" ixz="0" iyy="7.8999684e-07" iyz="0" izz="8e-08" />
    </inertial>
  </link>
  <joint name="j2s6s300_joint_finger_tip_3" type="revolute">
    <parent link="j2s6s300_link_finger_3" />
    <child link="j2s6s300_link_finger_tip_3" />
    <axis xyz="0 0 1" />
    <origin rpy="0 0 0" xyz="0.044 -0.003 0" />
    <limit effort="2" lower="0" upper="2" velocity="1" />
  </joint>
  <transmission name="j2s6s300_joint_finger_tip_3_trans">
    <type>transmission_interface/SimpleTransmission</type>
    <joint name="j2s6s300_joint_finger_tip_3">
      <hardwareInterface>hardware_interface/EffortJointInterface</hardwareInterface>
    </joint>
    <actuator name="j2s6s300_joint_finger_tip_3_actuator">
      <hardwareInterface>hardware_interface/EffortJointInterface</hardwareInterface>
      <mechanicalReduction>1</mechanicalReduction>
    </actuator>
  </transmission>
</robot>